Workbook

Sheet Resumen Participantes
A7: RESUMEN PARTICIPANTES CARRERA DEPORTIVA
B9: Categorias | C9: Participantes
B11: ATLETISMO FEMENIL 5 Kms. (18 a 35 Años) | C11: ='Atl-Fml-5-kms-1a'!G345 -> 333
B12: ATLETISMO FEMENIL 5 Kms. (36 Años) en adelante | C12: ='Atl-Fml-5-kms-2a'!G70 -> 59
B14: ATLETISMO VARONIL 5 Kms. (18 a 35 Años) | C14: ='Atl-Vnl-5-kms-1a'!G277 -> 260
B15: ATLETISMO VARONIL 5 Kms. (36 Años) en adelante | C15: ='Atl-Vnl-5-kms-2a'!G138 -> 121
B17: ATLETISMO FEMENIL 10 Kms. (18 a 35 Años) | C17: ='Atl-Fml-10-kms-1a'!G79 -> 70
B18: ATLETISMO FEMENIL 10 Kms. (36 Años) en adelante | C18: ='Atl-Fml-10-kms-2a'!I21 -> 9
B20: ATLETISMO VARONIL 10 Kms. (18 a 35 Años) | C20: ='Atl-Vnl-10-kms-1a'!I147 -> 131
B21: ATLETISMO VARONIL 10 Kms. (36 Años) en adelante | C21: ='Atl-Vnl-10-kms-2a'!I63 -> 50
B24: Total de Participantes | C24: =SUM(C11:C23) -> 1033

Sheet Atl-Fml-5-kms-1a
A2: 7/o Aniversario Magnas Obras
A3: Agrupamiento de Ingenieros
A4: "Felipe Angeles"
A6: A T L E T I S M O F E M E N I L " 5 K m s. "
A7: 1 8 a 3 5 A Ñ O S
A9: No. | B9: Nombre | C9: Apellido Paterno | D9: Apellido Materno | E9: Edad | F9: Sexo | G9: Talla de Playera | H9: No. Concursante | I9: Firma Recibido | J9: Area o Frente | K9: Banco | L9: Referencia o Folio | M9: Importe | O9: CHICA | P9: MEDIANA | Q9: GRANDE | R9: EXTRA G. | S9: XXL
A10: 1 | B10: MARISOL | C10: CASTRO | D10: CANO | E10: 29 | F10: FEMENINO | G10: MEDIANA | K10: AZTECA | L10: 8196287 | M10: 200 | P10: 1
A11: 2 | B11: MARIA DE LOURDES | C11: GUTIERREZ | D11: LUNA | E11: 34 | F11: FEMENINO | G11: CHICA | K11: BBVA | L11: 57666160 | M11: 200 | O11: 1
A12: 3 | B12: EVA MARIA | C12: RAMIREZ | D12: PEREZ | E12: 30 | F12: FEMENINO | G12: CHICA | K12: AZTECA | L12: 8196287 | M12: 200 | O12: 1
A13: 4 | B13: ROXANA | C13: AGUILAR | D13: AVENDAÑO | E13: 34 | F13: FEMENINO | G13: CHICA | K13: AZTECA | L13: 8196287 | M13: 200 | O13: 1
A14: 5 | B14: LAURA DANIELA | C14: HERNANDEZ | D14: MACIAS | E14: 30 | F14: FEMENINO | G14: CHICA | K14: AZTECA | L14: 8196287 | M14: 200 | O14: 1
A15: 6 | B15: DULCE MARIANA | C15: LIMA | D15: HERNANDEZ | E15: 23 | F15: FEMENINO | G15: CHICA | K15: AZTECA | L15: 8196287 | M15: 200 | O15: 1
A16: 7 | B16: ERIKA | C16: TORRES | D16: MARQUES | E16: 22 | F16: FEMENINO | G16: CHICA | K16: AZTECA | L16: 8196287 | M16: 200 | O16: 1
A17: 8 | B17: STEPHANIE | C17: VELAZQUEZ | D17: ROMERO | E17: 31 | F17: FEMENINO | G17: MEDIANA | K17: AZTECA | L17: 8196287 | M17: 200 | P17: 1
A18: 9 | B18: LILIANA | C18: PEREZ | D18: ARIZA | E18: 33 | F18: FEMENINO | G18: CHICA | K18: AZTECA | L18: 8196287 | M18: 200 | O18: 1
A19: 10 | B19: INGRID YAMILE | C19: HERNANDEZ | D19: CHAVEZ | E19: 23 | F19: FEMENINO | G19: CHICA | K19: HSBC | L19: 240926 | M19: 200 | O19: 1
A20: 11 | B20: MARIA JOSE | C20: ANGELES | D20: ANGELES | E20: 23 | F20: FEMENINO | G20: CHICA | K20: BBVA | L20: 2409260 | M20: 200 | O20: 1
A21: 12 | B21: DULCE NOELIA | C21: FLORES | D21: LÓPEZ | E21: 25 | F21: FEMENINO | G21: CHICA | J21: MESA TIC | K21: BBVA | L21: 57514975 | M21: 200 | O21: 1
A22: 13 | B22: ALONDRA LETICIA | C22: BARAJAS | D22: RAMÍREZ | E22: 26 | F22: FEMENINO | G22: MEDIANA | J22: ITEYPF | K22: BBVA | L22: 59812071 | M22: 200 | P22: 1
A23: 14 | B23: LUCERO | C23: MEDINA | E23: 22 | F23: FEMENINO | G23: GRANDE | K23: BBVA | L23: 99877224 | M23: 200 | Q23: 1
A24: 15 | B24: YESSICA ABRIL | C24: RUIZ | D24: SALINAS | E24: 31 | F24: FEMENINO | G24: MEDIANA | K24: BBVA | L24: 93008096 | M24: 200 | P24: 1
A25: 16 | B25: GUADALUPE ITZEL | C25: PACHECO | D25: ANEL | E25: 23 | F25: FEMENINO | G25: CHICA | K25: AZTECA | L25: 4.3202693e+17 | M25: 200 | O25: 1
A26: 17 | B26: ALEJANDRA | C26: PÉREZ | D26: MAYORGA | E26: 29 | F26: FEMENINO | G26: CHICA | L26: 28915826 | M26: 200 | O26: 1
A27: 18 | B27: MARÍA TERESA | C27: DE BOQUE | D27: BERNAL | E27: 30 | F27: FEMENINO | G27: CHICA | J27: FRENTE 3 TRAMO 7 | K27: BBVA | L27: 20185878 | M27: 200 | O27: 1
A28: 19 | B28: Vanessa Noemi | C28: Cabrera | D28: Nava | E28: 26 | F28: FEMENINO | G28: CHICA | J28: FRENTE 5 MÉXICO - QUERÉTARO. | K28: BBVA | L28: 65315723 | M28: 600 | O28: 1
A29: 20 | B29: Hilda Abigail | C29: Ibarra | D29: Reyes | E29: 24 | F29: FEMENINO | G29: CHICA | J29: MESA DE CONTROL DE CALIDAD | K29: BBVA | L29: 94255108 | M29: 200 | O29: 1
A30: 21 | B30: Karina Vianey | C30: Campos | D30: Salgado | E30: 31 | F30: FEMENINO | G30: MEDIANA | K30: BBVA | L30: 88112206 | M30: 200 | P30: 1
A31: 22 | B31: TERESA ELIZABETH | C31: ALFARO | D31: RAMIREZ | E31: 32 | F31: FEMENINO | G31: CHICA | J31: FRENTE 3 TRAMO 7 | K31: BBVA | L31: 44396023 | M31: 200 | O31: 1
A32: 23 | B32: MIRIAM ALEJANDRA | C32: HERNÁNDEZ | D32: SÁNCHEZ | E32: 34 | F32: FEMENINO | G32: CHICA | J32: MESA ATN. AUDS. INTS. Y EXTS. | K32: BBVA | L32: 63911580 | M32: 200 | O32: 1
A33: 24 | B33: LILIANA | C33: MALDONADO | D33: RODRIGUEZ | E33: 26 | F33: FEMENINO | G33: CHICA | J33: MESA ATN. AUDS. INTS. Y EXTS. | M33: 200 | O33: 1
A34: 25 | B34: ANA KAREN | C34: WALDO | D34: BAUTISTA | E34: 24 | F34: FEMENINO | G34: CHICA | J34: MESA ATN. AUDS. INTS. Y EXTS. | M34: 200 | O34: 1
A35: 26 | B35: SANDRA KARIME | C35: SANTIAGO | D35: GARCÍA | E35: 35 | F35: FEMENINO | G35: GRANDE | J35: MESA SALVAMENTO ARQUEOLÓGICO | K35: BBVA | L35: 60185970 | M35: 200 | Q35: 1
A36: 27 | B36: KARLA | C36: REYES | D36: LOREDO | E36: 28 | F36: FEMENINO | G36: MEDIANA | J36: MESA DE TOPOGRAFÍA | K36: SCOTIANBANK | L36: 2.0260926e+24 | M36: 200 | P36: 1
A37: 28 | B37: PAOLA SARAHI | C37: GARCÍA | D37: VALENCIA | E37: 23 | F37: FEMENINO | G37: GRANDE | J37: CONTROL INTERNO Y ADMINISTRACIÓN DE RIESGOS | K37: BBVA | L37: 99815676 | M37: 200 | Q37: 1
A38: 29 | B38: ANA KAREN | C38: TREJO | D38: FLORES | E38: 26 | F38: FEMENINO | G38: CHICA | J38: MESA ATN. AUDS. INTS. Y EXTS. | K38: BBVA | L38: 74861722 | M38: 200 | O38: 1
A39: 30 | B39: MARISOL MONTSERRAT | C39: VELAZQUEZ | D39: DE LA CRUZ | E39: 29 | F39: FEMENINO | G39: MEDIANA | J39: MESA ESTRUCTURAS | K39: BANAMEX | L39: 8.5905777e+16 | M39: 200 | P39: 1
A40: 31 | B40: AMADA YESICA | C40: JIMÉNEZ | D40: ALBA | E40: 24 | F40: FEMENINO | G40: MEDIANA | J40: MIC | K40: SANTANDER | L40: 1710258 | M40: 200 | P40: 1
A41: 32 | B41: TANIA IVET | C41: JIMÉNEZ | D41: VALENZUELA | E41: 30 | F41: FEMENINO | G41: GRANDE | J41: F5 MEX-QRO | K41: NU | L41: NU3ANA5NEG8V9NOABKKKR2QIAS4M | M41: 200 | Q41: 1
A42: 33 | B42: JOSSELINNE | C42: ORTIZ | D42: GONZÁLEZ | E42: 27 | F42: FEMENINO | G42: EXTRA GRANDE | J42: F5 MEX-QRO | K42: NU | L42: NU3ANA5K458F9BIBMJO4LD9RON73 | M42: 200 | R42: 1
A43: 34 | B43: Maria Suarez Cruz | E43: 29 | F43: FEMENINO | G43: MEDIANA | J43: Frente 1 TPMP | M43: 200 | P43: 1
...

Sheet Atl-Fml-5-kms-2a
A2: 7/o Aniversario Magnas Obras
A3: Agrupamiento de Ingenieros
A4: "Felipe Angeles"
A7: A T L E T I S M O F E M E N I L " 5 K m s. "
A8: 3 6 A Ñ O S E N A D E L A N T E
A10: No. | B10: Nombre | C10: Apellido Paterno | D10: Apellido Materno | E10: Edad | F10: Sexo | G10: Talla de Playera | H10: No. Concursante | I10: Firma Recibido | J10: Area o Frente | K10: Banco | L10: Referencia o Folio | M10: Importe | O10: CHICA | P10: MEDIANA | Q10: GRANDE | R10: EXTRA G. | S10: XXL
A11: 1 | B11: VERONICA | C11: TOVAR | D11: SOLIS | E11: 54 | F11: FEMENINO | G11: MEDIANA | P11: 1
A12: 2 | B12: KAREN LIZBETH | C12: HERNÁNDEZ | D12: TENORIO | E12: 36 | F12: FEMENINO | G12: EXTRA GRANDE | K12: AZTECA | L12: 8196287 | M12: 200 | R12: 1
A13: 3 | B13: YAZMIN | C13: CASTRO | D13: COVARRUBIAS | E13: 40 | F13: FEMENINO | G13: GRANDE | K13: AZTECA | L13: 8196287 | M13: 200 | Q13: 1
A14: 4 | B14: MAYRA JOCELIN | C14: MENDIETA | D14: VISTRAIN | E14: 38 | F14: FEMENINO | G14: CHICA | K14: AZTECA | L14: 8196287 | M14: 200 | O14: 1
A15: 5 | B15: JESSICA | C15: GALINDO | D15: ROSALES | E15: 44 | F15: FEMENINO | G15: MEDIANA | K15: AZTECA | L15: 8196287 | M15: 200 | P15: 1
A16: 6 | B16: MAGADALENA | C16: SOSA | D16: ZANCHEZ | E16: 45 | F16: FEMENINO | G16: GRANDE | K16: BANAMEX | L16: 230346 | M16: 200 | Q16: 1
A17: 7 | B17: BETSY NAYELY | C17: VIGUERAS | D17: REYES | E17: 38 | F17: FEMENINO | G17: MEDIANA | K17: SPIN | M17: 200 | P17: 1
A18: 8 | B18: YURI JAZMIN | C18: SEBASTIAN | D18: VICENCIO | E18: 45 | F18: FEMENINO | G18: MEDIANA | K18: BANCOPPEL | L18: 2409260 | M18: 200 | P18: 1
A19: 9 | B19: JOVANA ORQUÍDEA | C19: DELGADO | D19: BARAJAS | E19: 39 | F19: FEMENINO | G19: MEDIANA | K19: BBVA | L19: 57230624 | M19: 200 | P19: 1
A20: 10 | B20: Jazmin Areli | C20: Flores | D20: Palomino | E20: 48 | F20: FEMENINO | G20: MEDIANA | K20: NU | L20: 250926 | M20: 200 | P20: 1
A21: 11 | B21: ALICIA | C21: CIPRIANO | D21: CAMINO | E21: 43 | F21: FEMENINO | G21: CHICA | J21: MESA CONTROL INTERNO Y ADMÓN DE RIESGOS | K21: BBVA | L21: 19433175 | M21: 200 | O21: 1
A22: 12 | B22: CRISTINA ELENA | C22: VELÁZQUEZ | D22: JIMÉNEZ | E22: 46 | F22: FEMENINO | G22: MEDIANA | J22: MÉXICO-QUERÉTARO F3 | K22: SCOTIANBANK | L22: 6287 | M22: 200 | P22: 1
A23: 13 | B23: MARÍA ANDRE | C23: JASSO | D23: SANCHEZ | E23: 50 | F23: FEMENINO | G23: GRANDE | J23: MESA TIC | K23: BANCO AZTECA | L23: 2609270111027076074H | M23: 200 | Q23: 1
A24: 14 | B24: Vanessa Enriquez | E24: 46 | G24: MEDIANA | P24: 1
A25: 15 | B25: GRACIELA | C25: VARGAS | D25: HERNÁNDEZ | E25: 57 | F25: FEMENINO | G25: MEDIANA | J25: CONTROL DE EQUIPAMIENTO PERMANENTE Y NO PERMANENTE | K25: BBVA | L25: 84926023 | M25: 200 | P25: 1
A26: 16 | B26: MARÍA GUADALUPE | C26: FLORES | D26: RODRÍGUEZ | E26: 44 | F26: FEMENINO | G26: MEDIANA | J26: MESA R.H. | K26: BANCO AZTECA | L26: 2609280111068904367H | M26: 1200 | P26: 1
A27: 17 | B27: FABIOLA | C27: LIMA | D27: GARCÍA | E27: 47 | F27: FEMENINO | G27: CHICA | J27: REV. ADQS. Y CONT. CONTAB. | K27: BANCOPPEL | L27: 50118163TRANSBPI28007596 | M27: 200 | O27: 1
A28: 18 | B28: Rocio | C28: Naval | D28: Lugo | E28: 46 | F28: FEMENINO | G28: MEDIANA | J28: Frente 7 | P28: 1
A29: 19 | B29: Norma Vianey | C29: Villegas | D29: Rueda | E29: 39 | F29: FEMENINO | G29: MEDIANA | J29: Frente 7 | P29: 1
A30: 20 | B30: ROSALIN | C30: FERNANDEZ | D30: LANDEROS | E30: 50 | F30: FEMENINO | G30: MEDIANA | J30: F-10 MEX-QRO | P30: 1
A31: 21 | B31: ANABELL | C31: JIMENEZ | D31: ESCAMILLA | E31: 51 | F31: FEMENINO | G31: GRANDE | J31: F-10 MEX-QRO | Q31: 1
A32: 22 | B32: ELIA IVONNE | C32: MENDEZ | D32: LEON | E32: 54 | F32: FEMENINO | G32: EXTRA GRANDE | J32: F-10 MEX-QRO | R32: 1
A33: 23 | B33: Guadalupe | C33: Flores | D33: Guzman | E33: 36 | G33: GRANDE | J33: Control de Almacenes y Suministros | Q33: 1
A34: 24 | B34: ANTONIETA | C34: BAUTISTA | D34: SANTIAGO | E34: 44 | G34: MEDIANA | J34: REV. ADQS. Y CONT. CONTAB. | P34: 1
A35: 25 | B35: Xanat | C35: Santes | D35: Hernández | E35: 37 | G35: CHICA | J35: REV. ADQS. Y CONT. CONTAB. | O35: 1
A36: 26 | B36: ANA KARINA | C36: MORALES | D36: MUÑOZ | E36: 36 | F36: FEMENINO | G36: CHICA | J36: EYP | O36: 1
A37: 27 | B37: KARLA MARIBEL | C37: BARRERA | D37: CORTÉS | E37: 39 | F37: FEMENINO | G37: GRANDE | J37: MESA REV. ADQS- Y CTL. CONTAB. | Q37: 1
A38: 28 | B38: LEONOR ALEJANDRINA | C38: MELLADO | D38: HERNÁNDEZ | E38: 48 | F38: FEMENINO | G38: EXTRA GRANDE | J38: MESA REV. ADQS- Y CTL. CONTAB. | R38: 1
A39: 29 | B39: AURORA | C39: ESTRADA | D39: ABURTO | E39: 41 | F39: FEMENINO | G39: GRANDE | J39: MESA REV. ADQS- Y CTL. CONTAB. | Q39: 1
A40: 30 | B40: ABRIL | C40: VILLALOBOS | D40: RAMIREZ | E40: 36 | F40: FEMENINO | G40: MEDIANA | J40: FRENTE 4 AIFA PACHUCA | P40: 1
A41: 31 | B41: ADRIANA | C41: PIÑA | D41: GONZÁLEZ | E41: 38 | F41: FEMENINO | G41: XL | J41: FRENTE 4 AIFA PACHUCA | R41: 1
A42: 32 | B42: ANA LILIA | C42: PINEDA | D42: HERNÁNDEZ | E42: 44 | F42: FEMENINO | G42: CHICA | J42: FRENTE 4 AIFA PACHUCA | O42: 1
A43: 33 | B43: NATIVIDAD | C43: PINEDA | D43: MONDRAGÓN | E43: 39 | F43: FEMENINO | G43: MEDIANA | J43: FRENTE 4 AIFA PACHUCA | P43: 1
A44: 34 | B44: EVA | C44: JIMENEZ | D44: GONZALEZ | E44: 43 | F44: FEMENINO | G44: MEDIANA | J44: FRENTE 4 AIFA PACHUCA | P44: 1
...

Sheet Atl-Fml-10-kms-1a
A2: 7/o Aniversario Magnas Obras
A3: Agrupamiento de Ingenieros
A4: "Felipe Angeles"
A6: A T L E T I S M O F E M E N I L " 1 0 K m s. "
A7: 1 8 a 3 5 A Ñ O S
A8: No. | B8: Nombre | C8: Apellido Paterno | D8: Apellido Materno | E8: Edad | F8: Sexo | G8: Talla de Playera | H8: No. Concursante | I8: Firma Recibido | J8: Area o Frente | K8: Banco | L8: Referencia | M8: Importe | O8: CHICA | P8: MEDIANA | Q8: GRANDE | R8: EXTRA G. | S8: XXL
A9: 1 | B9: SOFIA ISABEL | C9: YEPEZ | D9: MENESES | E9: 27 | F9: FEMENINO | G9: CHICA | L9: EFECTIVO | M9: 200 | O9: 1
A10: 2 | B10: MIRIAM LUCERO | C10: VAZQUEZ | D10: DE LEON | E10: 32 | F10: FEMENINO | G10: MEDIANA | L10: EFECTIVO | M10: 200 | P10: 1
A11: 3 | B11: SANTA GUADALUPE | C11: ESTEVEZ | D11: RESENDIZ | E11: 28 | F11: FEMENINO | G11: MEDIANA | K11: MERCADO PAGO | L11: 179687838167 | M11: 200 | P11: 1
A12: 4 | B12: BRENDA YEDIDA | C12: MARTINEZ | D12: CUECUECHA | E12: 31 | F12: FEMENINO | G12: CHICA | K12: BANAMEX | L12: 386523 | M12: 200 | O12: 1
A13: 5 | B13: SANDRA KARINA | C13: MORALES | D13: MENDEZ | E13: 31 | F13: FEMENINO | G13: CHICA | J13: FRENTE 3 TRAMO 7 | K13: MERCADO PAGO | L13: 180847106054 | M13: 200 | O13: 1
A14: 6 | B14: ADILENE | C14: RODRÍGUEZ | D14: AGUILAR | E14: 28 | F14: FEMENINO | G14: CHICA | K14: BBVA | L14: 72854302 | M14: 2600 | O14: 1
A15: 7 | B15: PRISCILA | C15: JIMÉNEZ | D15: PÉREZ | E15: 30 | F15: FEMENINO | G15: CHICA | K15: BBVA | L15: 72854302 | M15: 2600 | O15: 1
A16: 8 | B16: ANDREA | C16: RODRÍGUEZ | D16: AGUILAR | E16: 23 | F16: FEMENINO | G16: CHICA | K16: BBVA | L16: 72854302 | M16: 2600 | O16: 1
A17: 9 | B17: ANA ITZEL | C17: LOZADA | D17: NAJERA | E17: 24 | F17: FEMENINO | G17: CHICA | K17: BBVA | L17: 72854302 | M17: 2600 | O17: 1
A18: 10 | B18: GRESI RUBI | C18: CASIMIRO | D18: VELASQUEZ | E18: 30 | F18: FEMENINO | G18: CHICA | K18: BBVA | L18: 72854302 | M18: 2600 | O18: 1
A19: 11 | B19: María Fernanda | C19: Vázquez | D19: Maceda | E19: 26 | F19: FEMENINO | G19: CHICA | K19: BBVA | L19: 72854302 | M19: 2600 | O19: 1
A20: 12 | B20: Jennifer Delfina | C20: Ramirez | D20: Gómez | E20: 29 | F20: FEMENINO | G20: MEDIANA | K20: BBVA | L20: 65315723 | M20: 600 | P20: 1
A21: 13 | B21: FERNANDA | C21: MARTINEZ | D21: RANGEL | E21: 28 | F21: FEMENINO | G21: CHICA | K21: BANCOPPEL | L21: 50111670TRANSBPI79869616 | M21: 200 | O21: 1
A22: 14 | B22: VIOLETA LILIANA | C22: HERNÁNDEZ | D22: GÓMEZ | E22: 30 | F22: FEMENINO | G22: CHICA | K22: BBVA | L22: 24064893 | M22: 600 | O22: 1
A23: 15 | B23: MARTHA JACQUELINE | C23: MUÑOZ | D23: PAREDES | E23: 27 | F23: FEMENINO | G23: EXTRA GRANDE | K23: BBVA | L23: 24064893 | M23: 600 | R23: 1
A24: 16 | B24: KAREN CITLALI | C24: RODRÍGUEZ | D24: ROBLES | E24: 32 | F24: FEMENINO | G24: EXTRA GRANDE | K24: BBVA | L24: 24064893 | M24: 600 | R24: 1
A25: 17 | B25: SANDRA VICTORIA | C25: DÍAZ | D25: AGUIRRE | E25: 28 | F25: FEMENINO | G25: CHICA | K25: BBVA | L25: 31781810 | M25: 200 | O25: 1
A26: 18 | B26: HEYDI PAOLA | C26: PECH | D26: PÉREZ | E26: 26 | F26: FEMENINO | G26: MEDIANA | K26: MERCADO PAGO | L26: 179933475923 | M26: 200 | P26: 1
A27: 19 | B27: FERNANDA | C27: REYES | D27: URBAN | E27: 27 | F27: FEMENINO | G27: MEDIANA | K27: BBVA | L27: 81621028 | M27: 200 | P27: 1
A28: 20 | B28: ELDA | C28: MARGARITA | D28: OCEJO | E28: XEGUER | F28: FEMENINO | G28: CHICA | J28: TAP F1 | K28: BBVA | L28: 75052270 | M28: 200 | O28: 1
A29: 21 | B29: ALMA GUADALUPE | C29: SANCHEZ | D29: PEREZ | E29: 26 | F29: FEMENINO | G29: CHICA | J29: MESA INGENIERÍA ELÉCTRICA Y EQUIPAMIENTO INDUSTRIAL | K29: BANCOPPEL | L29: 50118052TRANSBPI91581330 | M29: 200 | O29: 1
A30: 22 | B30: VAITIARE | C30: MARTINEZ | D30: MARTINEZ | E30: 23 | F30: FEMENINO | G30: EXTRA CHICA | J30: RAMAL POXILÁ-MÉRIDA Y POXILÁ-HUNUCMÁ | K30: BBVA | L30: 34854426 | M30: 200 | O30: 1
A31: 23 | B31: MARIEL GUEVARA FIGUEROA | E31: 33 | F31: FEMENINO | G31: MEDIANA | J31: TERMINAL DE CARGA PROGRESO | P31: 1
A32: 24 | B32: DIANA EVELIN JIMENEZ COVA | E32: 30 | F32: FEMENINO | G32: CHICA | J32: TERMINAL DE CARGA PROGRESO | O32: 1
A33: 25 | B33: MARÍA JOSÉ | C33: VELÁZQUEZ | D33: MADRIGAL | E33: 31 | F33: FEMENINO | G33: MEDIANA | J33: MESA REV. ADQS. Y CTL. CONTAB. | K33: BBVA | L33: 71927754 | M33: 200 | P33: 1
A34: 26 | B34: KARINA | C34: FLORES | D34: SILVA | E34: 26 | F34: FEMENINO | G34: CHICA | J34: TERMINAL MULTIMODAL PALENQUE | O34: 1
A35: 27 | B35: ARANZA AMAIRANI | C35: SANTIAGO | D35: SANCHEZ | E35: 31 | F35: FEMENINO | G35: MEDIANA | J35: TERMINAL MULTIMODAL PALENQUE | P35: 1
A36: 28 | B36: TERESA | C36: GARCIA | D36: MAXIMO | E36: 28 | F36: FEMENINO | G36: MEDIANA | J36: TERMINAL MULTIMODAL PALENQUE | P36: 1
A37: 29 | B37: LIZBETH | C37: GONZALEZ | D37: SANCHEZ | E37: 27 | F37: FEMENINO | G37: CHICA | J37: TERMINAL MULTIMODAL PALENQUE | O37: 1
A38: 30 | B38: MIRIAM VANESSA | C38: PARRA | D38: VARGAS | E38: 28 | F38: FEMENINO | G38: CHICA | J38: MESA O FRENTE: FRENTE 2 MÉX-QTO | O38: 1
A39: 31 | B39: Yhenny Yuliana | C39: Soto | D39: Diaz | E39: 30 | F39: FEMENINO | G39: CHICA | J39: Mesa de Rev. Adqs. y Ctl. Cont. | O39: 1
A40: 32 | B40: ANDREA | C40: MARTINEZ | D40: PAREDES | E40: 25 | F40: FEMENINO | G40: CHICA | J40: FRENTE 7 POXILA - MÉRIDA | O40: 1
A41: 33 | B41: DIANA LEIDI | C41: MENDOZA | D41: DIAZ | E41: 30 | F41: FEMENINO | G41: CHICA | J41: MESA O FRENTE EN QUE LABORAN: REV. ADQ.Y CTL. CONTAB | P41: 1
A42: 34 | B42: JAZMIN LUCIA | C42: GOMEZ | D42: FLORES | E42: 26 | F42: FEMENINO | G42: MEDIANA | J42: MESA REV. ADQS. Y CTL. CONTAB. | O42: 1
...

Sheet Atl-Fml-10-kms-2a
A2: 7/o Aniversario Magnas Obras
A3: Agrupamiento de Ingenieros
A4: "Felipe Angeles"
A7: A T L E T I S M O F E M E N I L " 1 0 K m s. "
A8: 3 6 A Ñ O S E N A D E L A N T E
A10: No. | B10: Nombre | C10: Apellido Paterno | D10: Apellido Materno | E10: Edad | F10: Sexo | G10: Talla de Playera | H10: No. Concursante | I10: Firma Recibido | J10: Area o Frente | K10: Banco | L10: Referencia | M10: Importe | O10: CHICA | P10: MEDIANA | Q10: GRANDE | R10: EXTRA G. | S10: XXL
A11: 1 | B11: GUADALUPE | C11: GARCÍA | D11: GARCÍA | E11: 38 | F11: FEMENINO | G11: MEDIANA | K11: BANAMEX | L11: 613555 | M11: 200 | P11: 1
A12: 2 | B12: MARA | C12: MAYA | D12: YVENES | E12: 39 | F12: FEMENINO | G12: CHICA | J12: MESA REV. ADQS Y CTL. CONTAB | O12: 1
A13: 3 | B13: PAULA | C13: OJEDA | D13: SANCHEZ | E13: 50 | F13: FEMENINO | G13: MEDIANA | J13: TERMINAL MULTIODAL PALENQUE | P13: 1
A14: 4 | B14: FABIOLA GUADALUPE | C14: BARRIENTOS | D14: JIMENEZ | E14: 42 | F14: FEMENINO | G14: CHICA | J14: TERMINAL MULTIODAL PALENQUE | O14: 1
A15: 5 | B15: THALÍA | C15: MORGADO | D15: PÉREZ | E15: 37 | F15: FEMENINO | G15: MEDIANA | J15: F2 MÉX-QRO | P15: 1
A16: 6 | B16: MARÍA BERTHA | C16: DOLORES | D16: PALMERO | E16: 41 | F16: FEMENINO | G16: MEDIANA | J16: FRENTE 4 AIFA PACHUCA | P16: 1
A17: 7 | B17: CLAUDIA | C17: MUÑOZ | D17: LOZANO | E17: 41 | F17: FEMENINO | G17: MEDIANA | P17: 1
A18: 8 | B18: MÓNICA | C18: OLGUÍN | D18: CANDELARIA | E18: 31 | F18: FEMENINO | G18: MEDIANA | J18: F2 MÉX-QRO | P18: 1
A19: 9 | B19: MARLEN | C19: MORGADO | D19: PÉREZ | E19: 41 | F19: FEMENINO | G19: GRANDE | J19: F2 MÉX-QRO | Q19: 1
H21: CONCURSANTES | I21: =O21+P21+Q21+R21+S21 -> 9 | O21: =SUM(O11:O20) -> 2 | P21: =SUM(P11:P20) -> 6 | Q21: =SUM(Q11:Q20) -> 1 | R21: =SUM(R11:R20) -> 0 | S21: =SUM(S11:S20) -> 0

Sheet Atl-Vnl-5-kms-1a
A2: 7/o Aniversario Magnas Obras
A3: Agrupamiento de Ingenieros
A4: "Felipe Angeles"
A6: A T L E T I S M O V A R O N I L " 5 K m s. "
A7: 1 8 a 3 5 A Ñ O S
A9: No. | B9: Nombre | C9: Apellido Paterno | D9: Apellido Materno | E9: Edad | F9: Sexo | G9: Talla de Playera | H9: No. Concursante | I9: Firma Recibido | J9: Area o Frente | K9: Banco | L9: Referencia | M9: Importe | O9: CHICA | P9: MEDIANA | Q9: GRANDE | R9: EXTRA G. | S9: XXL
B10: JESUS OMAR | C10: JUAREZ | D10: TOVAR | E10: 25 | F10: MASCULINO | G10: GRANDE | K10: BBVA | L10: 86688192 | M10: 200 | Q10: 1
B11: MIGUEL DE JESÚS | C11: ROBLERO | D11: CANCINO | E11: 34 | F11: MASCULINO | G11: EXTRA GRANDE | K11: AZTECA | L11: 8196287 | M11: 200 | R11: 1
B12: CARLOS DANIEL | C12: CORTES | D12: JIMENEZ. | E12: 32 | F12: MASCULINO | G12: GRANDE | K12: AZTECA | L12: 8196287 | M12: 200 | Q12: 1
B13: JOSE JUAN | C13: GONZALEZ | D13: VERA | E13: 24 | F13: MASCULINO | G13: EXTRA GRANDE | K13: AZTECA | L13: 8196287 | M13: 200 | R13: 1
B14: ERIK ALEJANDRO | C14: NOYOLA | D14: GARCIA. | E14: 35 | F14: MASCULINO | G14: GRANDE | K14: AZTECA | L14: 8196287 | M14: 200 | Q14: 1
B15: BRIAN RAFAEL | C15: RODRIGUEZ | D15: FRANCO. | E15: 32 | F15: MASCULINO | G15: EXTRA GRANDE | K15: AZTECA | L15: 8196287 | M15: 200 | R15: 1
B16: ROGELIO | C16: PEÑA | D16: CANO | E16: 24 | F16: MASCULINO | G16: MEDIANA | K16: AZTECA | L16: 8196287 | M16: 200 | P16: 1
B17: MIGUEL ANGEL | C17: URBINA | D17: HERNANDEZ | E17: 33 | F17: MASCULINO | G17: MEDIANA | K17: AZTECA | L17: 8196287 | M17: 200 | P17: 1
B18: ABRAHAM OSWALDO | C18: FLORES | D18: YATA | E18: 27 | F18: MASCULINO | G18: MEDIANA | K18: AZTECA | L18: 8196287 | M18: 200 | P18: 1
B19: JACIEL ISACK | C19: DELGADO | D19: SILVA | E19: 25 | F19: MASCULINO | G19: CHICA | K19: AZTECA | L19: 8196287 | M19: 200 | O19: 1
B20: JOSÉ CARLOS | C20: SALINAS | D20: ROJAS | E20: 26 | F20: MASCULINO | G20: XXL | K20: BBVA | L20: 61002521 | M20: 200 | S20: 1
B21: FRANCISCO JAVIER | C21: CANDANEDO | D21: ALVAREZ | E21: 35 | F21: MASCULINO | G21: MEDIANA | K21: HSBC | L21: 240926 | M21: 200 | P21: 1
B22: JOSÉ EDUARDO | C22: MENDOZA | D22: MENA | E22: 26 | F22: MASCULINO | G22: MEDIANA | K22: SANTANDER | L22: 3445804 | M22: 200 | P22: 1
B23: JONATHAN | C23: ESTRADA | D23: MONTES DE OCA | E23: 32 | F23: MASCULINO | G23: MEDIANA | K23: AZTECA | L23: 234239 | M23: 200 | P23: 1
B24: JOSE CARLOS | C24: MARTÍNEZ | D24: PÉREZ | E24: 35 | F24: MASCULINO | G24: GRANDE | K24: MERCADO PAGO | L24: 180848070354 | M24: 200 | Q24: 1
B25: FELIX | C25: ESTRADA | D25: MORALES | E25: 35 | F25: MASCULINO | G25: MEDIANA | K25: BBVA | L25: 2509260 | M25: 200 | P25: 1
B26: Carlos Enrique | C26: Hernández | D26: Serna | E26: 29 | F26: MASCULINO | G26: CHICA | K26: BBVA | L26: 77292686 | M26: 200 | O26: 1
B27: Luis Antonio | C27: Sánchez | D27: Torres | E27: 26 | F27: MASCULINO | G27: EXTRA GRANDE | K27: BBVA | L27: 94712494 | M27: 200 | R27: 1
B28: Luis Ricardo | C28: Rivera | D28: Hernández | E28: 32 | F28: MASCULINO | G28: MEDIANA | K28: BBVA | L28: 41184447 | M28: 200 | P28: 1
B29: ULISES | C29: VARGAS | D29: SANTOS | E29: 27 | F29: MASCULINO | G29: MEDIANA | J29: FRENTE 5 MÉXICO - QUERÉTARO. | K29: HSBC | L29: 260926 | M29: 200 | P29: 1
B30: OSVALDO | C30: JIMÉNEZ | D30: ANTONIO | E30: 25 | F30: MASCULINO | G30: MEDIANA | J30: MESA DE CONTROL DE CALIDAD | P30: 1
B31: HUGO | C31: BRITO | D31: ALANIS | E31: 26 | F31: MASCULINO | G31: GRANDE | J31: MESA DE ROPOGRAFÍA | K31: BBVA | L31: 34976741 | M31: 200 | Q31: 1
B32: OSCAR ALFREDO | C32: JUÁREZ | D32: HERNÁNDEZ | E32: 32 | F32: MASCULINO | G32: CHICA | J32: CONTROL INTERNO Y ADMINISTRACIÓN DE RIESGOS | K32: BBVA | L32: 61270203 | M32: 200 | O32: 1
B33: ADRIAN FERNANDO | C33: LÓPEZ | D33: AGUILAR | E33: 30 | F33: MASCULINO | G33: GRANDE | J33: CONTROL INTERNO Y ADMINISTRACIÓN DE RIESGOS | K33: BBVA | L33: 37631828 | M33: 200 | Q33: 1
B34: DUSTIN | C34: CERÓN | D34: LLERA | E34: 31 | F34: MASCULINO | G34: GRANDE | J34: TAP F1 | K34: SCOTIANBANK | L34: 2.0260926e+29 | M34: 200 | Q34: 1
B35: MARIO | C35: FLORES | D35: MUÑOZ | E35: 29 | F35: MASCULINO | G35: GRANDE | J35: RAMAL POXILÁ-MÉRIDA Y POXILÁ-HUNUCMÁ | K35: BBVA | L35: 85625389 | M35: 200 | Q35: 1
B36: JORGE | C36: LUVIANOS | D36: RAMOS | E36: 33 | F36: MASCULINO | G36: MEDIANA | J36: RAMAL POXILÁ-MÉRIDA Y POXILÁ-HUNUCMÁ | L36: 38129325 | M36: 200 | P36: 1
B37: JOSE ANTONIO | C37: MARTÍNEZ | D37: VARGAS | E37: 30 | F37: MASCULINO | G37: EXTRA GRANDE | J37: MESA RIYSA | R37: 1
B38: Ismael | C38: Flores | D38: Perales | E38: 34 | F38: MASCULINO | G38: MEDIANA | J38: Frente 1 TPMP | P38: 1
B39: ASIEL | C39: VALDES | D39: COSIO | E39: 27 | F39: MASCULINO | G39: GRANDE | J39: MESA REPOSICIÓN DE INFRAESTRUCTURA Y SERVICIOS AFECTADOS | Q39: 1
B40: Víctor Alberto Jandete Torres | E40: 30 | F40: MASCULINO | G40: GRANDE | J40: Mesa de Control Interno y Admon Riesgos. | Q40: 1
B41: FABIÁN ARTURO | C41: RESENDIS | D41: MARTÍNEZ | E41: 31 | F41: MASCULINO | G41: EXTRA GRANDE | J41: MESA DE COMBUSTIBLES Y LUBRICANTES. | R41: 1
B42: MISAEL ISAIAS TREJO GUERRERO | E42: 26 | F42: MASCULINO | G42: XXL | J42: TERMINAL DE CARGA PROGRESO | S42: 1
B43: Esaú | C43: González | D43: Reyes | E43: 25 | F43: MASCULINO | G43: MEDIANA | J43: Mesa de Estimaciones | P43: 1
...

Sheet Atl-Vnl-5-kms-2a
A1: 7/o Aniversario Magnas Obras
A2: Agrupamiento de Ingenieros
A3: "Felipe Angeles"
A4: A T L E T I S M O V A R O N I L " 5 K m s. "
A5: 3 6 A Ñ O S E N A D E L A N T E
A7: No. | B7: Nombre | C7: Apellido Paterno | D7: Apellido Materno | E7: Edad | F7: Sexo | G7: Talla de Playera | H7: No. Concursante | I7: Firma Recibido | J7: Area o Frente | K7: Banco | L7: Referencia | M7: Importe | O7: CHICA | P7: MEDIANA | Q7: GRANDE | R7: EXTRA G. | S7: XXL
B8: SAID | C8: PIOQUINTO | D8: VARGAS | E8: 49 | F8: MASCULINO | G8: GRANDE | K8: BBVA | L8: 86688192 | M8: 200 | Q8: 1
B9: JOSÉ JULIÁN | C9: SANTANA | D9: ZAMORA | E9: 39 | F9: MASCULINO | G9: MEDIANA | K9: AZTECA | L9: 8196287 | M9: 200 | P9: 1
B10: DAVID ZARATE GUZMAN | C10: ZARATE | D10: GUZMAN | E10: 48 | F10: MASCULINO | G10: GRANDE | K10: AZTECA | L10: 8196287 | M10: 200 | Q10: 1
B11: ISRAEL | C11: PEREZ | D11: HERNANDEZ | E11: 38 | F11: MASCULINO | G11: MEDIANA | K11: AZTECA | L11: 8196287 | M11: 200 | P11: 1
B12: MARIO ALEJANDRO | C12: HERNANDEZ | D12: GARCIA | E12: 48 | F12: MASCULINO | G12: XXL | K12: AZTECA | L12: 8196287 | M12: 200 | S12: 1
B13: FERNANDO | C13: JERÓNIMO | D13: ACHIQUEN | E13: 45 | F13: MASCULINO | G13: MEDIANA | K13: MERCADO P. | L13: 180750656894 | M13: 200 | P13: 1
B14: ERICK FAUSTINO | C14: SÁNCHEZ | D14: OCHOA | E14: 48 | F14: MASCULINO | G14: GRANDE | K14: MERCADO P. | L14: 179823038643 | M14: 200 | Q14: 1
B15: CARLOS ALBERTO | C15: MIX | D15: ZAPATA | E15: 50 | F15: MASCULINO | G15: MEDIANA | K15: BBVA | L15: 35424120 | M15: 200 | P15: 1
B16: ERNESTO DANIEL | C16: ROMERO | D16: CASTILLO | E16: 36 | F16: MASCULINO | G16: GRANDE | K16: BBVA | L16: 59242080 | M16: 200 | Q16: 1
B17: ISMAEL | C17: GARCÍA | D17: GARCÍA | E17: 38 | F17: MASCULINO | G17: MEDIANA | K17: BBVA | L17: 67838612 | M17: 200 | P17: 1
B18: SAUL | C18: CASTÁN | D18: MORALES | E18: 54 | F18: MASCULINO | G18: GRANDE | K18: AZTECA | L18: 815914 | M18: 200 | Q18: 1
B19: Albert | C19: Ramirez | D19: Riras | E19: 68 | F19: MASCULINO | G19: MEDIANA | K19: Depósito OXXO | L19: 6287 | M19: 200 | P19: 1
B20: EDGAR | C20: TORRES | D20: MARTINEZ | E20: 41 | F20: MASCULINO | G20: CHICA | K20: BANCOPPEL | L20: 50111670TRANSBPI79914246 | M20: 200 | O20: 1
B21: ERIK | C21: TORRES | D21: MARTINEZ | E21: 41 | F21: MASCULINO | G21: MEDIANA | K21: BANCOPPEL | L21: 50111670TRANSBPI79822866 | M21: 200 | P21: 1
B22: JOSÉ GERARDO | C22: GARCÍA | D22: MELENDEZ | E22: 56 | F22: MASCULINO | G22: MEDIANA | K22: BANCOPPEL | L22: 50118163TRANSBPI79751746 | M22: 200 | P22: 1
B23: JOSÉ ÁNGEL | C23: MARIN | D23: CRUZ | E23: 53 | F23: MASCULINO | G23: GRANDE | K23: BANCOPPEL | L23: 50117838TRANSBPI81152812 | M23: 200 | Q23: 1
B24: ARTURO | C24: ÁVILA | D24: PÉREZ | E24: 58 | F24: MASCULINO | G24: GRANDE | K24: BBVA | L24: 46904645 | M24: 200 | Q24: 1
B25: ERNESTO | C25: ROMERO | D25: CASTILLO | E25: 36 | F25: MASCULINO | G25: GRANDE | J25: MIC | K25: BBVA | L25: 59242080 | M25: 200 | Q25: 1
B26: ERICK | C26: NERY | D26: GARCÍA | E26: 45 | F26: MASCULINO | G26: GRANDE | K26: SANTANDER | L26: 2895717 | M26: 200 | Q26: 1
B27: ORLANDO | C27: ARELLANO | D27: MIRANDA | E27: 61 | F27: MASCULINO | G27: MEDIANA | J27: MESA REVISIÓN DE ADQUISICIONES Y CONTROL CONTABLE | K27: BANCOPPEL | L27: 50116736TRANSBPI9533850 | M27: 200 | P27: 1
B28: CARLOS ANTONIO | C28: GÓMEZ | D28: LUCAS | E28: 56 | F28: MASCULINO | G28: MEDIANA | J28: MESA DE TRANSPORTES | K28: SPIN OXXO | L28: SPIN-20260928153403GD23ST8E | M28: 200 | P28: 1
B29: MAURICIO JESÚS | C29: SUÁREZ | D29: DÍAZ | E29: 60 | F29: MASCULINO | G29: EXTRA GRANDE | J29: REPOSICIÓN DE INFRAESTRUCTURA Y SERVICIOS AFECTADOS | K29: BBVA | L29: 42966843 | M29: 200 | R29: 1
B30: Neftalee Oscar Soto Diaz | E30: 36 | F30: MASCULINO | G30: MEDIANA | J30: Control Interno y Administración de Riesgos. | P30: 1
B31: Ruben Rodríguez Ramirez, | E31: 62 | F31: MASCULINO | G31: GRANDE | J31: Control Interno y Administración de Riesgos. | Q31: 1
B32: Israel | C32: Benítez | D32: Nava | E32: 43 | F32: MASCULINO | G32: MEDIANA | J32: Mesa de Estimaciones | P32: 1
B33: TOMÁS | C33: LOPEZ | D33: VÁZQUEZ | E33: 38 | F33: MASCULINO | G33: EXTRA GRANDE | J33: Control Interno y Administración de Riesgos. | R33: 1
B34: HUGO | C34: TAPIA | D34: COLIN. | E34: 39 | F34: MASCULINO | G34: MEDIANA | J34: MESA DE COMBUSTIBLES Y LUBRICANTES. | P34: 1
B35: JULIO CÉSAR | C35: MORALES | D35: LIMÓN | E35: 30 | F35: MASCULINO | G35: GRANDE | J35: Frente 7 Ramal | Q35: 1
B36: GUSTAVO | C36: ORTIZ | D36: AVILA | E36: 38 | F36: MASCULINO | G36: MEDIANA | J36: MESA MIC | K36: BBVA | L36: 97807908 | M36: 200 | P36: 1
B37: VALENTIN | C37: RAMOS | D37: TOMAS | E37: 44 | F37: MASCULINO | G37: MEDIANA | J37: MESA DE SEGURIDAD Y SALUD EN EL TRABAJO | K37: BANCO AZTECA | M37: 600 | P37: 1
B38: OSCAR | C38: RAMÍREZ | D38: CONTRERAS | E38: 55 | F38: MASCULINO | G38: GRANDE | J38: MESA R.H. | K38: BANCO AZTECA | L38: 2609280111068904367H | M38: 1200 | Q38: 1
B39: PEDRO | C39: CRUZ | D39: GUZMAN | E39: 50 | F39: MASCULINO | G39: GRANDE | J39: TERMINAL MULTIMODAL PALENQUE | Q39: 1
B40: ANTONIO | C40: VIXTHA | D40: HERNANDEZ | E40: 36 | F40: MASCULINO | G40: MEDIANA | J40: TERMINAL MULTIMODAL PALENQUE | P40: 1
B41: Frankie | C41: Torres | D41: Barrios | E41: 43 | F41: MASCULINO | G41: GRANDE | J41: Mesa de Transportes | Q41: 1
...

Sheet Atl-Vnl-10-kms-1a
A1: 7/o Aniversario Magnas Obras
A2: Agrupamiento de Ingenieros
A3: "Felipe Angeles"
A4: A T L E T I S M O V A R O N I L " 1 0 K m s. "
A5: 1 8 a 3 5 A Ñ O S
A7: No. | B7: Nombre | C7: Apellido Paterno | D7: Apellido Materno | E7: Edad | F7: Sexo | G7: Talla de Playera | H7: No. Concursante | I7: Firma Recibido | J7: Area o Frente | K7: Banco | L7: Referencia | M7: Importe | O7: CHICA | P7: MEDIANA | Q7: GRANDE | R7: EXTRA G. | S7: XXL
B8: JOSE LUIS | C8: CAMACHO | D8: CAZAREZ | E8: 27 | F8: MASCULINO | G8: GRANDE | K8: MERCADO PAGO | L8: 179685761979 | M8: 200 | Q8: 1
B9: ALEX JAIR | C9: SOLIS | D9: VILLA | E9: 25 | F9: MASCULINO | G9: MEDIANA | J9: MESA TIC | K9: MERCADO PAGO | L9: 179689802855 | M9: 200 | P9: 1
B10: ANGEL EMMANUEL | C10: ESTRELLA | D10: RAJÓN | E10: 26 | F10: MASCULINO | G10: GRANDE | J10: MESA TIC | K10: BBVA | L10: 63458234 | M10: 200 | Q10: 1
B11: ABRAHAM | C11: SANCHEZ | D11: RIVERA | E11: 29 | F11: MASCULINO | G11: GRANDE | K11: AZTECA | L11: 8196287 | M11: 200 | Q11: 1
B12: OSWALDO | C12: OSORIO | D12: PEÑAFLOR | E12: 49 | F12: MASCULINO | G12: MEDIANA | K12: BANAMEX | L12: 604797 | M12: 200 | P12: 1
B13: ISRAEL AYRTON | C13: BAUTISTA | D13: ANDRADE | E13: 32 | F13: MASCULINO | G13: CHICA | J13: FRENTE 3 TRAMO 7 | K13: BBVA | L13: 3751580 | M13: 200 | O13: 1
B14: Gerardo | C14: Rodriguez | D14: Avilés | E14: 34 | F14: MASCULINO | G14: GRANDE | K14: BBVA | L14: 72854302 | M14: 2600 | Q14: 1
B15: Samuel | C15: Valadez | D15: Pérez | E15: 26 | F15: MASCULINO | G15: MEDIANA | K15: BBVA | L15: 72854302 | M15: 2600 | P15: 1
B16: Benhur Roberto | C16: Éboli | D16: Román | E16: 31 | F16: MASCULINO | G16: MEDIANA | K16: BBVA | L16: 72854302 | M16: 2600 | P16: 1
B17: Héctor Abraham | C17: Arias | D17: Bautista | E17: 30 | F17: MASCULINO | G17: EXTRA GRANDE | K17: BBVA | L17: 72854302 | M17: 2600 | R17: 1
B18: Jafet Aldair | C18: Bustor | D18: Aguilar | E18: 28 | F18: MASCULINO | G18: EXTRA GRANDE | K18: BBVA | L18: 72854302 | M18: 2600 | R18: 1
B19: Francisco Javier | C19: Miranda | D19: Ixta | E19: 28 | F19: MASCULINO | G19: XXL | K19: BBVA | L19: 72854302 | M19: 2600 | S19: 1
B20: Idar | C20: Alexis | D20: Martínez | E20: 30 | F20: MASCULINO | G20: GRANDE | K20: BBVA | L20: 72854302 | M20: 2600 | Q20: 1
B21: Luis Jesus Joatan | C21: Leon | D21: Angeles | E21: 29 | F21: MASCULINO | G21: GRANDE | K21: BBVA | L21: 65315723 | M21: 600 | Q21: 1
B22: Francisco | C22: Olguín | D22: Holguín | E22: 33 | F22: MASCULINO | G22: GRANDE | K22: NU | L22: NU3AMRD3UIPE9H6P12R1PAP5CDK0 | M22: 200 | Q22: 1
B23: MARCO ANTONIO | C23: LÓPEZ | D23: LÓPEZ | E23: 31 | F23: MASCULINO | G23: GRANDE | J23: FRENTE MÉX-QRO-FRENTE 1 | K23: MERCADO PAGO | L23: 180910240988 | M23: 200 | Q23: 1
B24: EDGAR DANIEL | C24: CERVANTES | D24: REYES | E24: 27 | F24: MASCULINO | G24: MEDIANA | P24: 1
B25: JAFETH | C25: OLVERA | D25: ESTUDILLO | E25: 29 | F25: MASCULINO | G25: MEDIANA | J25: ELECTRICA | K25: BBVA | L25: 54171516 | M25: 200 | P25: 1
B26: MARTÍN IVÁN | C26: ALBARRÁN | D26: CONDA | E26: 28 | F26: MASCULINO | G26: MEDIANA | J26: TPMP F1 AIFA-PACHUCA | K26: BBVA | L26: 89279857 | M26: 200 | P26: 1
B27: JAVIER | C27: BARRIENTOS | D27: CUEVAS | E27: 25 | F27: MASCULINO | G27: CHICA | J27: TAP F1 | K27: NU | L27: NU3AMVTV4QDI86T8682VJDBI3FBN | M27: 200 | O27: 1
B28: LUIS JAIR | C28: HERNÁNDEZ | D28: CRUZ | E28: 29 | F28: MASCULINO | G28: MEDIANA | J28: RAMAL POXILÁ-MÉRIDA Y POXILÁ-HUNUCMÁ | K28: BANCO AZTECA | L28: 2609280111046942356H | M28: 200 | P28: 1
B29: ALEJANDRO | C29: GUEVARA | D29: FIGUEROA | E29: 27 | F29: MASCULINO | G29: EXTRA GRANDE | J29: TERMINAL DE CARGA PROGRESO | R29: 1
B30: JOSE ENRIQUE | C30: SANCHEZ | D30: MAGAÑA | E30: 29 | F30: MASCULINO | G30: EXTRA GRANDE | J30: TERMINAL DE CARGA PROGRESO | R30: 1
B31: LUIS CARLOS | C31: ANCHEYTA | D31: ORTEGA | E31: 28 | F31: MASCULINO | G31: MEDIANA | J31: MESA DE EJECUCIÓN DE OBRA | P31: 1
B32: HUMBERTO HERNÁNDEZ RIVERA | E32: 31 | F32: MASCULINO | G32: MEDIANA | J32: MESA DE ATENCIÓN A AUDITORÍAS INTERNAS Y EXTERNAS | P32: 1
B33: Ruben Alberto | C33: Olguin | D33: Baños | E33: 27 | F33: MASCULINO | G33: MEDIANA | P33: 1
B34: JOSE BALTAZAR | C34: RAMOS | D34: ESPAÑA | E34: 35 | F34: MASCULINO | G34: MEDIANA | J34: MESA DE ATENCIÓN A AUDITORÍAS INTERNAS Y EXTERNAS | P34: 1
B35: FLAVIO RAFAEL | C35: CONSTANTINO | D35: MARCIAL | E35: 31 | F35: MASCULINO | G35: MEDIANA | J35: IFMQ-F3 | P35: 1
B36: EDGAR ENRIQUE | C36: SOSA | D36: MONROY | E36: 21 | F36: MASCULINO | G36: MEDIANA | J36: F2 MÉX-QRO | K36: BBVA | L36: 14476247 | M36: 200 | P36: 1
B37: CHRISTIAN | C37: ALVARADO | D37: CASTILLO | E37: 27 | F37: MASCULINO | G37: GRANDE | J37: ITEPA Y CAF | K37: BANAMEX | L37: 8.5901829e+16 | M37: 200 | Q37: 1
B38: SEBASTIÁN | C38: HERNÁNDEZ | D38: DINORÍN | E38: 25 | F38: MASCULINO | G38: GRANDE | J38: ITE YPF | K38: MERCADO PAGO | L38: 180383770997 | M38: 200 | Q38: 1
B39: IVAN ALEJANDRO | C39: LOPEZ | D39: DIAZ | E39: 25 | F39: MASCULINO | G39: CHICA | J39: TERMINAL MULTIMODAL PALENQUE | O39: 1
B40: RENATO | C40: JAIMES | D40: IBARRA | E40: 31 | F40: MASCULINO | G40: MEDIANA | J40: TERMINAL MULTIMODAL PALENQUE | P40: 1
B41: HUGO | C41: PEÑA | D41: LOPEZ | E41: 29 | F41: MASCULINO | G41: GRANDE | J41: TERMINAL MULTIMODAL PALENQUE | Q41: 1
...

Sheet Atl-Vnl-10-kms-2a
A1: 7/o Aniversario Magnas Obras
A2: Agrupamiento de Ingenieros
A3: "Felipe Angeles"
A5: A T L E T I S M O V A R O N I L " 1 0 K m s. "
A6: 3 6 A Ñ O S E N A D E L A N T E
A8: No. | B8: Nombre | C8: Apellido Paterno | D8: Apellido Materno | E8: Edad | F8: Sexo | G8: Talla de Playera | H8: No. Concursante | I8: Firma Recibido | J8: Area o Frente | K8: Banco | L8: Referencia | M8: Importe | O8: CHICA | P8: MEDIANA | Q8: GRANDE | R8: EXTRA G. | S8: XXL
B9: ARTEMIO | C9: MÁRQUEZ | D9: VERA | E9: 53 | F9: MASCULINO | G9: GRANDE | K9: BANAMEX | L9: 758247 | M9: 200 | Q9: 1
B10: OCTAVIO | C10: GARDUÑO | D10: ESCOBEDO | E10: 46 | F10: MASCULINO | G10: MEDIANA | K10: BBVA | M10: 200 | P10: 1
B11: CESAR | C11: HERNÁNDEZ | D11: VEGA | E11: 40 | F11: MASCULINO | G11: MEDIANA | K11: BBVA | L11: 89353066 | M11: 200 | P11: 1
B12: Cristian Iván | C12: Coronel | D12: Sánchez | E12: 38 | F12: Masculino | G12: MEDIANA | K12: NU | L12: NU3AMRC2ILE29QQ93F7F6R0M114P | M12: 200 | P12: 1
B13: Ivan Noe | C13: Mardoniz | D13: Gutiérrez | E13: 37 | F13: Masculino | G13: EXTRA GRANDE | K13: BBVA | L13: 80248874 | M13: 200 | R13: 1
B14: JULIO EDUARDO | C14: HERNÁNDEZ | D14: VILLALBA | E14: 36 | F14: MASCULINO | G14: MEDIANA | J14: MESA INGENIERÍA ELÉCTRICA Y EQUIPAMIENTO INDUSTRIAL | K14: Mercado Pago | L14: 180913136200 | M14: 200 | P14: 1
B15: ERWIN | C15: FERNÁNDEZ | D15: SÁNCHEZ | E15: 39 | F15: MASCULINO | G15: CHICA | J15: MESA ATN. AUDS. INTS. Y EXTS. | K15: BANCOPPEL | L15: 50118163TRANSBPI79145346 | M15: 200 | O15: 1
B16: EDGAR ALBERTO | C16: AGUILAR | D16: GAVITO | E16: 49 | F16: MASCULINO | G16: MEDIANA | J16: MESA INGENIERÍA ELÉCTRICA Y EQUIPAMIENTO INDUSTRIAL | K16: MERCADO PAGO | L16: 180037910987 | M16: 200 | P16: 1
B17: FRANCISCO DE JESUS LOPEZ MORENO | E17: 38 | F17: MASCULINO | G17: CHICA | J17: TERMINAL DE CARGA PROGRESO | O17: 1
B18: CARLOS EDUARDO PEREZ GRESS | E18: 38 | F18: MASCULINO | G18: MEDIANA | J18: TERMINAL DE CARGA PROGRESO | P18: 1
B19: TAURINO | C19: MARTINEZ | D19: DOMÍNGUEZ | E19: 54 | F19: MASCULINO | G19: GRANDE | J19: MESA REV. ADQS Y CTL. CONTAB | Q19: 1
B20: LUIS FERNANDO | C20: GARCÍA | D20: RAMÍREZ | E20: 43 | F20: MASCULINO | G20: GRANDE | J20: MESA REV. ADQS. Y CTL. CONTAB | K20: BBVA | L20: 1012492 | M20: 200 | Q20: 1
B21: LUIS ANTONIO | C21: MEZA | D21: VILLALVA | E21: 36 | F21: MASCULINO | G21: MEDIANA | J21: MESA DE AUDITORIAS | K21: BANCO AZTECA | L21: 2609280111081398975H | M21: 200 | P21: 1
B22: CARLOS ALBERTO | C22: COLMENERO | D22: ORTIZ | E22: 37 | F22: MASCULINO | G22: GRANDE | J22: GRUPO ENLACE | K22: BBVA | L22: 9598440 | M22: 200 | Q22: 1
B23: ÁLVARO | C23: TECUA | D23: SÁNCHEZ | E23: 46 | F23: MASCULINO | G23: GRANDE | J23: ATN. AUDS. INTS. Y EXTS. | K23: BANCOPPEL | L23: 50118163TRANSBPI27987326 | M23: 200 | Q23: 1
B24: ALFREDO | C24: CRUZ | D24: GARCÍA | E24: 45 | F24: MASCULINO | G24: GRANDE | J24: MESA ADQUISICIONES | K24: BANAMEX | L24: 353485 | M24: 200 | Q24: 1
B25: CARLOS ANDRES | C25: HERNANDEZ | D25: AZUARA | E25: 49 | F25: MASCULINO | G25: GRANDE | J25: TERMINAL MULTIMODAL PALENQUE | Q25: 1
B26: FRANCISCO | C26: ROSETTE | D26: REYES | E26: 50 | G26: CHICA | J26: MESA REV. ADQS. Y CTL. CONTAB. | O26: 1
B27: Ricardo | C27: Escalona | D27: Flores | E27: 57 | G27: GRANDE | J27: MESA REV. ADQS. Y CTL. CONTAB. | Q27: 1
B28: Juan Carlos | C28: García | D28: Ramírez | E28: 41 | G28: GRANDE | J28: Mesa Rev. Adqs. y C.C. | Q28: 1
B29: OSCAR GENARO | C29: LOPEZ | D29: SORIANO | E29: 44 | G29: MEDIANA | J29: MESA DE TERRACERIAS Y PAVIMENTOS | P29: 1
B30: GABRIEL | C30: MENDOZA | D30: RUIZ | E30: 47 | F30: MASCULINO | G30: MEDIANA | J30: MESA REV. ADQS. Y CTL. CONTAB | P30: 1
B31: RAFAEL | C31: SEGURA | D31: MARQUEZ | E31: 49 | F31: MASCULINO | G31: MEDIANA | J31: MESA REV. ADQS. Y CTL. CONTAB | P31: 1
B32: CARLOS | C32: LÓPEZ | D32: SANTI | E32: 38 | F32: MASCULINO | G32: MEDIANA | J32: GRUPO ENLACE | P32: 1
B33: ALAN MICHAEL | C33: ARREONDO | D33: SALAZAR | E33: 34 | F33: MASCULINO | G33: GRANDE | Q33: 1
B34: TAURINO | C34: MARTÍNEZ | D34: DOMINGUEZ | E34: 54 | F34: MASCULINO | G34: GRANDE | J34: MESA REV. ADQS. Y CTL. CONTAB. | Q34: 1
B35: TIMOTEO | C35: JIMÉNEZ | D35: JIMÉNEZ | E35: 49 | F35: MASCULINO | G35: MEDIANA | J35: MESA REV. ADQS. Y CTL. CONTAB. | P35: 1
B36: ENRIQUE | C36: LADIN | D36: VÁZQUEZ | E36: 46 | F36: MASCULINO | G36: MEDIANA | J36: MESA REV. ADQS. Y CTL. CONTAB. | P36: 1
B37: AUGUSTO | C37: ABARCA | D37: GUILLERMO | E37: 40 | F37: MASCULINO | G37: CHICA | J37: MESA DE ACARREOS | O37: 1
B38: DIEGO | C38: DÍAZ | D38: ÁVILA | E38: 38 | F38: MASCULINO | G38: MEDIANA | J38: FRENTE 4 AIFA PACHUCA | P38: 1
B39: EDGAR URIEL | C39: RODRIGUEZ | D39: SAUCEDO | E39: 53 | F39: MASCULINO | G39: XL | J39: FRENTE 4 AIFA PACHUCA | S39: 1
B41: JUAN ALEJANDRO | C41: BAUTIST | D41: BAUTISTA | E41: 38 | F41: MASCULINO | G41: MEDIANA | J41: MESA ARCHIVO REV. ADQS. Y CTL. CONTAB | P41: 1
B42: MANUEL | C42: ARCOS | D42: GUTIERREZ | E42: 40 | F42: MASCULINO | G42: GRANDE | J42: MESA ARCHIVO REV. ADQS. Y CTL. CONTAB | Q42: 1
B44: Angel | C44: Aparicio | D44: Lopez | E44: 48 | F44: MASCULINO | G44: MEDIANA | J44: FRENTE 7 | P44: 1
...

Sheet R PLayeras
A3: CHICA | B3: MEDIANA | C3: GRANDE | D3: EXTRA G. | E3: XXL
A5: ='Atl-Fml-5-kms-1a'!O345+'Atl-Fml-5-kms-2a'!O70+'Atl-Vnl-5-kms-1a'!O277+'Atl-Vnl-5-kms-2a'!O138+'Atl-Fml-10-kms-1a'!O79+'Atl-Fml-10-kms-2a'!O21+'Atl-Vnl-10-kms-1a'!O147+'Atl-Vnl-10-kms-2a'!O63 -> 226 | B5: ='Atl-Fml-5-kms-1a'!P345+'Atl-Fml-5-kms-2a'!P70+'Atl-Vnl-5-kms-1a'!P277+'Atl-Vnl-5-kms-2a'!P138+'Atl-Fml-10-kms-1a'!P79+'Atl-Fml-10-kms-2a'!P21+'Atl-Vnl-10-kms-1a'!P147+'Atl-Vnl-10-kms-2a'!P63 -> 460 | C5: ='Atl-Fml-5-kms-1a'!Q345+'Atl-Fml-5-kms-2a'!Q70+'Atl-Vnl-5-kms-1a'!Q277+'Atl-Vnl-5-kms-2a'!Q138+'Atl-Fml-10-kms-1a'!Q79+'Atl-Fml-10-kms-2a'!Q21+'Atl-Vnl-10-kms-1a'!Q147+'Atl-Vnl-10-kms-2a'!Q63 -> 254 | D5: ='Atl-Fml-5-kms-1a'!R345+'Atl-Fml-5-kms-2a'!R70+'Atl-Vnl-5-kms-1a'!R277+'Atl-Vnl-5-kms-2a'!R138+'Atl-Fml-10-kms-1a'!R79+'Atl-Fml-10-kms-2a'!R21+'Atl-Vnl-10-kms-1a'!R147+'Atl-Vnl-10-kms-2a'!R63 -> 74 | E5: ='Atl-Fml-5-kms-1a'!S345+'Atl-Fml-5-kms-2a'!S70+'Atl-Vnl-5-kms-1a'!S277+'Atl-Vnl-5-kms-2a'!S138+'Atl-Fml-10-kms-1a'!S79+'Atl-Fml-10-kms-2a'!S21+'Atl-Vnl-10-kms-1a'!S147+'Atl-Vnl-10-kms-2a'!S63 -> 19
A7: =A5+B5+C5+D5+E5 -> 1033 | B7: TOTAL PLAYERAS
